<?xml version="1.0" ?>
<sdf version="1.9">
  <model name="quadrotor">
    <self_collide>false</self_collide>

    <!-- ===== Main Body ===== -->
    <link name="base_link">
      <inertial>
        <mass>1.5</mass>
        <inertia>
          <ixx>0.029125</ixx><iyy>0.029125</iyy><izz>0.055225</izz>
          <ixy>0</ixy><ixz>0</ixz><iyz>0</iyz>
        </inertia>
      </inertial>
      <visual name="body_visual">
        <geometry><box><size>0.4 0.4 0.1</size></box></geometry>
        <material><ambient>0.1 0.1 0.8 1</ambient><diffuse>0.1 0.1 0.8 1</diffuse></material>
      </visual>
      <collision name="body_collision">
        <geometry><box><size>0.4 0.4 0.1</size></box></geometry>
      </collision>

      <!-- Downward-facing camera -->
      <sensor name="camera" type="camera">
        <pose>0 0 -0.06 0 1.5708 0</pose>
        <camera>
          <horizontal_fov>1.047</horizontal_fov>
          <image><width>640</width><height>480</height><format>R8G8B8</format></image>
          <clip><near>0.1</near><far>100</far></clip>
        </camera>
        <always_on>1</always_on>
        <update_rate>30</update_rate>
        <visualize>true</visualize>
        <topic>/drone/camera</topic>
      </sensor>
    </link>

    <!-- ===== Rotor 0: Front-Left (CCW) ===== -->
    <link name="rotor_0">
      <pose>0.13 0.22 0.023 0 0 0</pose>
      <inertial>
        <mass>0.025</mass>
        <inertia><ixx>9.75e-7</ixx><iyy>4.17e-5</iyy><izz>4.26e-5</izz></inertia>
      </inertial>
      <visual name="rotor_0_visual">
        <geometry><cylinder><radius>0.1</radius><length>0.005</length></cylinder></geometry>
        <material><ambient>0 1 0 1</ambient><diffuse>0 1 0 1</diffuse></material>
      </visual>
      <collision name="rotor_0_collision">
        <geometry><cylinder><radius>0.1</radius><length>0.005</length></cylinder></geometry>
      </collision>
    </link>
    <joint name="rotor_0_joint" type="revolute">
      <parent>base_link</parent><child>rotor_0</child>
      <axis>
        <xyz>0 0 1</xyz>
        <limit><lower>-1e+16</lower><upper>1e+16</upper></limit>
        <dynamics><damping>0.004</damping></dynamics>
      </axis>
    </joint>

    <!-- ===== Rotor 1: Back-Right (CCW) ===== -->
    <link name="rotor_1">
      <pose>-0.13 -0.22 0.023 0 0 0</pose>
      <inertial>
        <mass>0.025</mass>
        <inertia><ixx>9.75e-7</ixx><iyy>4.17e-5</iyy><izz>4.26e-5</izz></inertia>
      </inertial>
      <visual name="rotor_1_visual">
        <geometry><cylinder><radius>0.1</radius><length>0.005</length></cylinder></geometry>
        <material><ambient>0 1 0 1</ambient><diffuse>0 1 0 1</diffuse></material>
      </visual>
      <collision name="rotor_1_collision">
        <geometry><cylinder><radius>0.1</radius><length>0.005</length></cylinder></geometry>
      </collision>
    </link>
    <joint name="rotor_1_joint" type="revolute">
      <parent>base_link</parent><child>rotor_1</child>
      <axis>
        <xyz>0 0 1</xyz>
        <limit><lower>-1e+16</lower><upper>1e+16</upper></limit>
        <dynamics><damping>0.004</damping></dynamics>
      </axis>
    </joint>

    <!-- ===== Rotor 2: Front-Right (CW) ===== -->
    <link name="rotor_2">
      <pose>0.13 -0.22 0.023 0 0 0</pose>
      <inertial>
        <mass>0.025</mass>
        <inertia><ixx>9.75e-7</ixx><iyy>4.17e-5</iyy><izz>4.26e-5</izz></inertia>
      </inertial>
      <visual name="rotor_2_visual">
        <geometry><cylinder><radius>0.1</radius><length>0.005</length></cylinder></geometry>
        <material><ambient>1 0 0 1</ambient><diffuse>1 0 0 1</diffuse></material>
      </visual>
      <collision name="rotor_2_collision">
        <geometry><cylinder><radius>0.1</radius><length>0.005</length></cylinder></geometry>
      </collision>
    </link>
    <joint name="rotor_2_joint" type="revolute">
      <parent>base_link</parent><child>rotor_2</child>
      <axis>
        <xyz>0 0 1</xyz>
        <limit><lower>-1e+16</lower><upper>1e+16</upper></limit>
        <dynamics><damping>0.004</damping></dynamics>
      </axis>
    </joint>

    <!-- ===== Rotor 3: Back-Left (CW) ===== -->
    <link name="rotor_3">
      <pose>-0.13 0.22 0.023 0 0 0</pose>
      <inertial>
        <mass>0.025</mass>
        <inertia><ixx>9.75e-7</ixx><iyy>4.17e-5</iyy><izz>4.26e-5</izz></inertia>
      </inertial>
      <visual name="rotor_3_visual">
        <geometry><cylinder><radius>0.1</radius><length>0.005</length></cylinder></geometry>
        <material><ambient>1 0 0 1</ambient><diffuse>1 0 0 1</diffuse></material>
      </visual>
      <collision name="rotor_3_collision">
        <geometry><cylinder><radius>0.1</radius><length>0.005</length></cylinder></geometry>
      </collision>
    </link>
    <joint name="rotor_3_joint" type="revolute">
      <parent>base_link</parent><child>rotor_3</child>
      <axis>
        <xyz>0 0 1</xyz>
        <limit><lower>-1e+16</lower><upper>1e+16</upper></limit>
        <dynamics><damping>0.004</damping></dynamics>
      </axis>
    </joint>

    <!-- ===== Motor Model Plugins (one per rotor) ===== -->
    <plugin filename="gz-sim-multicopter-motor-model-system"
            name="gz::sim::systems::MulticopterMotorModel">
      <robotNamespace>drone</robotNamespace>
      <jointName>rotor_0_joint</jointName>
      <linkName>rotor_0</linkName>
      <turningDirection>ccw</turningDirection>
      <timeConstantUp>0.0125</timeConstantUp>
      <timeConstantDown>0.025</timeConstantDown>
      <maxRotVelocity>800</maxRotVelocity>
      <motorConstant>8.54858e-06</motorConstant>
      <momentConstant>0.06</momentConstant>
      <commandSubTopic>command/motor_speed</commandSubTopic>
      <motorNumber>0</motorNumber>
      <rotorDragCoefficient>8.06428e-05</rotorDragCoefficient>
      <rollingMomentCoefficient>1e-06</rollingMomentCoefficient>
      <motorSpeedPubTopic>motor_speed/0</motorSpeedPubTopic>
      <rotorVelocitySlowdownSim>10</rotorVelocitySlowdownSim>
    </plugin>

    <plugin filename="gz-sim-multicopter-motor-model-system"
            name="gz::sim::systems::MulticopterMotorModel">
      <robotNamespace>drone</robotNamespace>
      <jointName>rotor_1_joint</jointName>
      <linkName>rotor_1</linkName>
      <turningDirection>ccw</turningDirection>
      <timeConstantUp>0.0125</timeConstantUp>
      <timeConstantDown>0.025</timeConstantDown>
      <maxRotVelocity>800</maxRotVelocity>
      <motorConstant>8.54858e-06</motorConstant>
      <momentConstant>0.06</momentConstant>
      <commandSubTopic>command/motor_speed</commandSubTopic>
      <motorNumber>1</motorNumber>
      <rotorDragCoefficient>8.06428e-05</rotorDragCoefficient>
      <rollingMomentCoefficient>1e-06</rollingMomentCoefficient>
      <motorSpeedPubTopic>motor_speed/1</motorSpeedPubTopic>
      <rotorVelocitySlowdownSim>10</rotorVelocitySlowdownSim>
    </plugin>

    <plugin filename="gz-sim-multicopter-motor-model-system"
            name="gz::sim::systems::MulticopterMotorModel">
      <robotNamespace>drone</robotNamespace>
      <jointName>rotor_2_joint</jointName>
      <linkName>rotor_2</linkName>
      <turningDirection>cw</turningDirection>
      <timeConstantUp>0.0125</timeConstantUp>
      <timeConstantDown>0.025</timeConstantDown>
      <maxRotVelocity>800</maxRotVelocity>
      <motorConstant>8.54858e-06</motorConstant>
      <momentConstant>0.06</momentConstant>
      <commandSubTopic>command/motor_speed</commandSubTopic>
      <motorNumber>2</motorNumber>
      <rotorDragCoefficient>8.06428e-05</rotorDragCoefficient>
      <rollingMomentCoefficient>1e-06</rollingMomentCoefficient>
      <motorSpeedPubTopic>motor_speed/2</motorSpeedPubTopic>
      <rotorVelocitySlowdownSim>10</rotorVelocitySlowdownSim>
    </plugin>

    <plugin filename="gz-sim-multicopter-motor-model-system"
            name="gz::sim::systems::MulticopterMotorModel">
      <robotNamespace>drone</robotNamespace>
      <jointName>rotor_3_joint</jointName>
      <linkName>rotor_3</linkName>
      <turningDirection>cw</turningDirection>
      <timeConstantUp>0.0125</timeConstantUp>
      <timeConstantDown>0.025</timeConstantDown>
      <maxRotVelocity>800</maxRotVelocity>
      <motorConstant>8.54858e-06</motorConstant>
      <momentConstant>0.06</momentConstant>
      <commandSubTopic>command/motor_speed</commandSubTopic>
      <motorNumber>3</motorNumber>
      <rotorDragCoefficient>8.06428e-05</rotorDragCoefficient>
      <rollingMomentCoefficient>1e-06</rollingMomentCoefficient>
      <motorSpeedPubTopic>motor_speed/3</motorSpeedPubTopic>
      <rotorVelocitySlowdownSim>10</rotorVelocitySlowdownSim>
    </plugin>

    <!-- ===== Velocity Controller (with full rotorConfiguration) ===== -->
    <plugin filename="gz-sim-multicopter-control-system"
            name="gz::sim::systems::MulticopterVelocityControl">
      <robotNamespace>drone</robotNamespace>
      <commandSubTopic>cmd_vel</commandSubTopic>
      <enableSubTopic>enable</enableSubTopic>
      <comLinkName>base_link</comLinkName>
      <velocityGain>2.7 2.7 2.7</velocityGain>
      <attitudeGain>2 3 0.15</attitudeGain>
      <angularRateGain>0.4 0.52 0.18</angularRateGain>
      <maximumLinearAcceleration>2 2 2</maximumLinearAcceleration>
      <rotorConfiguration>
        <rotor>
          <jointName>rotor_0_joint</jointName>
          <forceConstant>8.54858e-06</forceConstant>
          <momentConstant>0.06</momentConstant>
          <direction>1</direction>
        </rotor>
        <rotor>
          <jointName>rotor_1_joint</jointName>
          <forceConstant>8.54858e-06</forceConstant>
          <momentConstant>0.06</momentConstant>
          <direction>1</direction>
        </rotor>
        <rotor>
          <jointName>rotor_2_joint</jointName>
          <forceConstant>8.54858e-06</forceConstant>
          <momentConstant>0.06</momentConstant>
          <direction>-1</direction>
        </rotor>
        <rotor>
          <jointName>rotor_3_joint</jointName>
          <forceConstant>8.54858e-06</forceConstant>
          <momentConstant>0.06</momentConstant>
          <direction>-1</direction>
        </rotor>
      </rotorConfiguration>
    </plugin>

  </model>
</sdf>
